<class 'ValueError'>: , Worker Worker_0002 failed while executing job 2
    Traceback (most recent call last):
      File "/home/max/prog/git/proton/proton/multipro/workers.py", line 173, in run
    *job.args, **job.kwargs)
      File "/home/max/prog/git/proton/proton/multipro/target.py", line 56, in __call__
    return self.function_or_instance(*args, **kwargs)
      File "demo.py", line 10, in fun
    raise ValueError()
    ValueError

<class 'ValueError'>: , Worker Worker_0002 failed while executing job 2
    Traceback (most recent call last):
      File "/home/max/prog/git/proton/proton/multipro/workers.py", line 173, in run
    *job.args, **job.kwargs)
      File "/home/max/prog/git/proton/proton/multipro/target.py", line 56, in __call__
    return self.function_or_instance(*args, **kwargs)
      File "demo.py", line 10, in fun
    raise ValueError()
    ValueError

<class 'ValueError'>: , Worker Worker_0005 failed while executing job 5
    Traceback (most recent call last):
      File "/home/max/prog/git/proton/proton/multipro/workers.py", line 173, in run
    *job.args, **job.kwargs)
      File "/home/max/prog/git/proton/proton/multipro/target.py", line 56, in __call__
    return self.function_or_instance(*args, **kwargs)
      File "demo.py", line 10, in fun
    raise ValueError()
    ValueError

<class 'ValueError'>: , Worker Worker_0004 failed while executing job 4
    Traceback (most recent call last):
      File "/home/max/prog/git/proton/proton/multipro/workers.py", line 173, in run
    *job.args, **job.kwargs)
      File "/home/max/prog/git/proton/proton/multipro/target.py", line 56, in __call__
    return self.function_or_instance(*args, **kwargs)
      File "demo.py", line 10, in fun
    raise ValueError()
    ValueError

<class 'ValueError'>: , Worker Worker_0002 failed while executing job 9
    Traceback (most recent call last):
      File "/home/max/prog/git/proton/proton/multipro/workers.py", line 173, in run
    *job.args, **job.kwargs)
      File "/home/max/prog/git/proton/proton/multipro/target.py", line 56, in __call__
    return self.function_or_instance(*args, **kwargs)
      File "demo.py", line 10, in fun
    raise ValueError()
    ValueError

<class 'ValueError'>: , Worker Worker_0003 failed while executing job 3
    Traceback (most recent call last):
      File "/home/max/prog/git/proton/proton/multipro/workers.py", line 173, in run
    *job.args, **job.kwargs)
      File "/home/max/prog/git/proton/proton/multipro/target.py", line 56, in __call__
    return self.function_or_instance(*args, **kwargs)
      File "demo.py", line 10, in fun
    raise ValueError()
    ValueError

<class 'ValueError'>: , Worker Worker_0001 failed while executing job 1
    Traceback (most recent call last):
      File "/home/max/prog/git/proton/proton/multipro/workers.py", line 173, in run
    *job.args, **job.kwargs)
      File "/home/max/prog/git/proton/proton/multipro/target.py", line 56, in __call__
    return self.function_or_instance(*args, **kwargs)
      File "demo.py", line 10, in fun
    raise ValueError()
    ValueError

<class 'ValueError'>: , Worker Worker_0001 failed while executing job 10
    Traceback (most recent call last):
      File "/home/max/prog/git/proton/proton/multipro/workers.py", line 173, in run
    *job.args, **job.kwargs)
      File "/home/max/prog/git/proton/proton/multipro/target.py", line 56, in __call__
    return self.function_or_instance(*args, **kwargs)
      File "demo.py", line 10, in fun
    raise ValueError()
    ValueError

<class 'ValueError'>: , Worker Worker_0007 failed while executing job 7
    Traceback (most recent call last):
      File "/home/max/prog/git/proton/proton/multipro/workers.py", line 173, in run
    *job.args, **job.kwargs)
      File "/home/max/prog/git/proton/proton/multipro/target.py", line 56, in __call__
    return self.function_or_instance(*args, **kwargs)
      File "demo.py", line 10, in fun
    raise ValueError()
    ValueError

<class 'ValueError'>: , Worker Worker_0008 failed while executing job 8
    Traceback (most recent call last):
      File "/home/max/prog/git/proton/proton/multipro/workers.py", line 173, in run
    *job.args, **job.kwargs)
      File "/home/max/prog/git/proton/proton/multipro/target.py", line 56, in __call__
    return self.function_or_instance(*args, **kwargs)
      File "demo.py", line 10, in fun
    raise ValueError()
    ValueError

<class 'ValueError'>: , Worker Worker_0006 failed while executing job 6
    Traceback (most recent call last):
      File "/home/max/prog/git/proton/proton/multipro/workers.py", line 173, in run
    *job.args, **job.kwargs)
      File "/home/max/prog/git/proton/proton/multipro/target.py", line 56, in __call__
    return self.function_or_instance(*args, **kwargs)
      File "demo.py", line 10, in fun
    raise ValueError()
    ValueError

